Workbook

Sheet 2_IPM Mpio y Dpt
A1: ID | B1: Municipio | C1: IPM Municipal
A2: 05001 | B2: MEDELLÍN | C2: 12.8
A3: 05002 | B3: ABEJORRAL | C3: 40.6
A4: 05004 | B4: ABRIAQUÍ | C4: 34.8
A5: 05021 | B5: ALEJANDRÍA | C5: 31.9
A6: 05030 | B6: AMAGÁ | C6: 22.9
A7: 05031 | B7: AMALFI | C7: 43.3
A8: 05034 | B8: ANDES | C8: 40.1
A9: 05036 | B9: ANGELÓPOLIS | C9: 30.7
A10: 05038 | B10: ANGOSTURA | C10: 53.8
A11: 05040 | B11: ANORÍ | C11: 53.3
A12: 05042 | B12: SANTA FÉ DE ANTIOQUIA | C12: 29.7
A13: 05044 | B13: ANZÁ | C13: 47.1
... A1123: 99773 | B1123: CUMARIBO | C1123: 91.4

Sheet 4_IPM Mpio dominios
A1: ID | B1: Municipio | C1: IPM | D1: Cabeceras | E1: IPM Centros poblados y rural disperso
A2: 05001 | B2: MEDELLÍN | C2: 12.8 | D2: 12.6 | E2: 22.9
A3: 05002 | B3: ABEJORRAL | C3: 40.6 | D3: 24.1 | E3: 51.4
A4: 05004 | B4: ABRIAQUÍ | C4: 34.8 | D4: 13.6 | E4: 45.2
A5: 05021 | B5: ALEJANDRÍA | C5: 31.9 | D5: 15.8 | E5: 53.7
A6: 05030 | B6: AMAGÁ | C6: 22.9 | D6: 17.7 | E6: 27.7
A7: 05031 | B7: AMALFI | C7: 43.3 | D7: 26.3 | E7: 66.3
A8: 05034 | B8: ANDES | C8: 40.1 | D8: 25.2 | E8: 54.4
A9: 05036 | B9: ANGELÓPOLIS | C9: 30.7 | D9: 22.3 | E9: 36.1
A10: 05038 | B10: ANGOSTURA | C10: 53.8 | D10: 25.5 | E10: 62.1
A11: 05040 | B11: ANORÍ | C11: 53.3 | D11: 39.1 | E11: 66.7
A12: 05042 | B12: SANTA FÉ DE ANTIOQUIA | C12: 29.7 | D12: 19 | E12: 51.2
A13: 05044 | B13: ANZÁ | C13: 47.1 | D13: 24 | E13: 52.4
... A1090: 91001 | B1090: LETICIA | C1090: 48.4 | D1090: 41.9 | E1090: 67.8
A1091: 91263 | B1091: EL ENCANTO | C1091: 77.5 | D1091: -- | E1091: 77.5
A1092: 91405 | B1092: LA CHORRERA | C1092: 88.1 | D1092: -- | E1092: 88.1
A1093: 91407 | B1093: LA PEDRERA | C1093: 90.9 | D1093: -- | E1093: 90.9
A1094: 91430 | B1094: LA VICTORIA | C1094: 96.4 | D1094: -- | E1094: 96.4
A1095: 91460 | B1095: MIRITÍ - PARANÁ | C1095: 91.2 | D1095: -- | E1095: 91.2
A1096: 91530 | B1096: PUERTO ALEGRÍA | C1096: 82.4 | D1096: -- | E1096: 82.4
A1097: 91536 | B1097: PUERTO ARICA | C1097: 84.6 | D1097: -- | E1097: 84.6
A1098: 91540 | B1098: PUERTO NARIÑO | C1098: 70.4 | D1098: 51.6 | E1098: 79.2
A1099: 91669 | B1099: PUERTO SANTANDER | C1099: 88.7 | D1099: -- | E1099: 88.7
A1100: 91798 | B1100: TARAPACÁ | C1100: 80 | D1100: -- | E1100: 80
A1101: 94001 | B1101: INÍRIDA | C1101: 67.2 | D1101: 59.5 | E1101: 85.6
A1102: 94343 | B1102: BARRANCOMINAS | C1102: 86.5 | D1102: -- | E1102: 86.5
A1103: 94663 | B1103: MAPIRIPANA | C1103: 95.5 | D1103: -- | E1103: 95.5
A1104: 94883 | B1104: SAN FELIPE | C1104: 88.3 | D1104: -- | E1104: 88.3
A1105: 94884 | B1105: PUERTO COLOMBIA | C1105: 96.3 | D1105: -- | E1105: 96.3
A1106: 94885 | B1106: LA GUADALUPE | C1106: 84.1 | D1106: -- | E1106: 84.1
A1107: 94886 | B1107: CACAHUAL | C1107: 90.1 | D1107: -- | E1107: 90.1
A1108: 94887 | B1108: PANA PANA | C1108: 98.5 | D1108: -- | E1108: 98.5
A1109: 94888 | B1109: MORICHAL | C1109: 95.7 | D1109: -- | E1109: 95.7
A1110: 95001 | B1110: SAN JOSÉ DEL GUAVIARE | C1110: 42.1 | D1110: 33.8 | E1110: 65.1
A1111: 95015 | B1111: CALAMAR | C1111: 58 | D1111: 54.7 | E1111: 61.3
A1112: 95025 | B1112: EL RETORNO | C1112: 51.5 | D1112: 33.4 | E1112: 59.2
A1113: 95200 | B1113: MIRAFLORES | C1113: 66.7 | D1113: 54.7 | E1113: 73
A1114: 97001 | B1114: MITÚ | C1114: 74.8 | D1114: 44.9 | E1114: 91.4
A1115: 97161 | B1115: CARURÚ | C1115: 81.1 | D1115: 60.3 | E1115: 94.8
A1116: 97511 | B1116: PACOA | C1116: 98.4 | D1116: -- | E1116: 98.4
...

Sheet 6_Privaciones IPM Dpt-Mpio
C1: Privaciones Municipios
A2: ID | B2: Municipio | C2: Analfabetismo | D2: Bajo logro educativo | E2: Barreras a servicios para cuidado de la primera infancia | F2: Barreras de acceso a servicios de salud | G2: Tasa de dependencia | H2: Hacinamiento crítico | I2: Inadecuada eliminación de excretas | J2: Inasistencia escolar | K2: Material inadecuado de paredes exteriores | L2: Material inadecuado de pisos | M2: Rezago escolar | N2: Sin acceso a fuente de agua mejorada | O2: Sin aseguramiento en salud | P2: Trabajo infantil | Q2: Trabajo informal
A3: 05001 | B3: MEDELLÍN | C3: 5 | D3: 35.2 | E3: 1.4 | F3: 2.6 | G3: 22.8 | H3: 5.4 | I3: 2 | J3: 3.1 | K3: 0.7 | L3: 0.2 | M3: 12.5 | N3: 1.5 | O3: 15.9 | P3: 0.5 | Q3: 71
A4: 05002 | B4: ABEJORRAL | C4: 18.9 | D4: 81.7 | E4: 1.3 | F4: 3.2 | G4: 30.2 | H4: 5.2 | I4: 23.6 | J4: 5 | K4: 0.3 | L4: 1.6 | M4: 20.3 | N4: 32.3 | O4: 8.8 | P4: 3.6 | Q4: 87.5
A5: 05004 | B5: ABRIAQUÍ | C5: 13 | D5: 66.8 | E5: 1.3 | F5: 1.9 | G5: 37.4 | H5: 5.4 | I5: 39.6 | J5: 2.4 | K5: 0.8 | L5: 3.4 | M5: 13.1 | N5: 34.4 | O5: 11.7 | P5: 1.2 | Q5: 87.6
A6: 05021 | B6: ALEJANDRÍA | C6: 15.7 | D6: 72.9 | E6: 1.2 | F6: 0.5 | G6: 36.7 | H6: 4.1 | I6: 3.7 | J6: 2.5 | K6: 0.4 | L6: 2.5 | M6: 17.9 | N6: 26.8 | O6: 11 | P6: 1.5 | Q6: 87.1
A7: 05030 | B7: AMAGÁ | C7: 15.4 | D7: 64.4 | E7: 1.3 | F7: 4.3 | G7: 27.2 | H7: 4.8 | I7: 5.6 | J7: 4.7 | K7: 0.3 | L7: 1.4 | M7: 15.7 | N7: 4.6 | O7: 14.1 | P7: 0.8 | Q7: 69.5
A8: 05031 | B8: AMALFI | C8: 19.1 | D8: 73.1 | E8: 1.4 | F8: 5.2 | G8: 32.3 | H8: 6.3 | I8: 32.7 | J8: 5.9 | K8: 4.6 | L8: 9.5 | M8: 23.2 | N8: 36.4 | O8: 12.1 | P8: 3.5 | Q8: 86.4
A9: 05034 | B9: ANDES | C9: 18.8 | D9: 72.1 | E9: 1.5 | F9: 4.7 | G9: 29.9 | H9: 5 | I9: 33.6 | J9: 5.5 | K9: 0.4 | L9: 0.7 | M9: 18.2 | N9: 28.3 | O9: 12.7 | P9: 2.6 | Q9: 87.2
A10: 05036 | B10: ANGELÓPOLIS | C10: 18.4 | D10: 74.3 | E10: 1.4 | F10: 1.5 | G10: 29.2 | H10: 5.6 | I10: 16.8 | J10: 3.9 | K10: 1.2 | L10: 2.3 | M10: 20.6 | N10: 10.8 | O10: 11.1 | P10: 1.7 | Q10: 74
A11: 05038 | B11: ANGOSTURA | C11: 25.3 | D11: 81.2 | E11: 1.9 | F11: 10.9 | G11: 38.7 | H11: 7.4 | I11: 49.6 | J11: 6.7 | K11: 0.3 | L11: 10.3 | M11: 25.8 | N11: 26.1 | O11: 9.4 | P11: 3.6 | Q11: 87
A12: 05040 | B12: ANORÍ | C12: 19.9 | D12: 75.6 | E12: 2 | F12: 5.8 | G12: 38.1 | H12: 8.9 | I12: 54.5 | J12: 7.7 | K12: 3.7 | L12: 8.3 | M12: 28.2 | N12: 43.9 | O12: 9.7 | P12: 3.9 | Q12: 89.1
A13: 05042 | B13: SANTA FÉ DE ANTIOQUIA | C13: 15.7 | D13: 62.1 | E13: 1.3 | F13: 1.4 | G13: 29.8 | H13: 9.7 | I13: 5.9 | J13: 4 | K13: 1.2 | L13: 9.4 | M13: 19.7 | N13: 9.2 | O13: 12.7 | P13: 1.3 | Q13: 81.9
A14: 05044 | B14: ANZÁ | C14: 27.8 | D14: 83.9 | E14: 2.1 | F14: 6.7 | G14: 30.6 | H14: 6.1 | I14: 35.3 | J14: 6.4 | K14: 0.8 | L14: 8.5 | M14: 25.2 | N14: 22.1 | O14: 8.5 | P14: 3.8 | Q14: 87.1
... A1124: 99773 | B1124: CUMARIBO | C1124: 26 | D1124: 85.4 | E1124: 18.8 | F1124: 5.4 | G1124: 83.1 | H1124: 38.9 | I1124: 85 | J1124: 21.1 | K1124: 41.8 | L1124: 76.8 | M1124: 47.3 | N1124: 79.1 | O1124: 44.6 | P1124: 1 | Q1124: 96.5

Sheet 8_Privaciones Mpio dominio
A1: ID | B1: Municipio | C1: Analfabetismo | F1: Bajo logro educativo | I1: Barreras a servicios para cuidado de la primera infancia | L1: Barreras de acceso a servicios de salud | O1: Tasa de dependencia | R1: Hacinamiento crítico | U1: Inadecuada eliminación de excretas | X1: Inasistencia escolar | AA1: Material inadecuado de paredes exteriores | AD1: Material inadecuado de pisos | AG1: Rezago escolar | AJ1: Sin acceso a fuente de agua mejorada | AM1: Sin aseguramiento en salud | AP1: Trabajo infantil | AS1: Trabajo informal
C2: Total | D2: Cabeceras | E2: Centros poblados y rural disperso | F2: Total | G2: Cabeceras | H2: Centros poblados y rural disperso | I2: Total | J2: Cabeceras | K2: Centros poblados y rural disperso | L2: Total | M2: Cabeceras | N2: Centros poblados y rural disperso | O2: Total | P2: Cabeceras | Q2: Centros poblados y rural disperso | R2: Total | S2: Cabeceras | T2: Centros poblados y rural disperso | U2: Total | V2: Cabeceras | W2: Centros poblados y rural disperso | X2: Total | Y2: Cabeceras | Z2: Centros poblados y rural disperso | AA2: Total | AB2: Cabeceras | AC2: Centros poblados y rural disperso | AD2: Total | AE2: Cabeceras | AF2: Centros poblados y rural disperso | AG2: Total | AH2: Cabeceras | AI2: Centros poblados y rural disperso | AJ2: Total | AK2: Cabeceras | AL2: Centros poblados y rural disperso | AM2: Total | AN2: Cabeceras | AO2: Centros poblados y rural disperso | AP2: Total | AQ2: Cabeceras | AR2: Centros poblados y rural disperso | AS2: Total | AT2: Cabeceras | AU2: Centros poblados y rural disperso
A3: 05001 | B3: MEDELLÍN | C3: 5 | D3: 4.9 | E3: 11.6 | F3: 35.2 | G3: 34.9 | H3: 54.4 | I3: 1.4 | J3: 1.4 | K3: 2 | L3: 2.6 | M3: 2.6 | N3: 3 | O3: 22.8 | P3: 22.8 | Q3: 23.7 | R3: 5.4 | S3: 5.5 | T3: 3.1 | U3: 2 | V3: 1.7 | W3: 15.7 | X3: 3.1 | Y3: 3.1 | Z3: 4.8 | AA3: 0.7 | AB3: 0.7 | AC3: 0.4 | AD3: 0.2 | AE3: 0.2 | AF3: 1.8 | AG3: 12.5 | AH3: 12.5 | AI3: 13.9 | AJ3: 1.5 | AK3: 1.3 | AL3: 16.9 | AM3: 15.9 | AN3: 15.9 | AO3: 15.5 | AP3: 0.5 | AQ3: 0.5 | AR3: 1.1 | AS3: 71 | AT3: 70.9 | AU3: 77.3
A4: 05002 | B4: ABEJORRAL | C4: 18.9 | D4: 15.1 | E4: 21.7 | F4: 81.7 | G4: 65 | H4: 94 | I4: 1.3 | J4: 0.7 | K4: 1.7 | L4: 3.2 | M4: 2.2 | N4: 3.9 | O4: 30.2 | P4: 32.5 | Q4: 28.6 | R4: 5.2 | S4: 5.9 | T4: 4.6 | U4: 23.6 | V4: 4.3 | W4: 37.9 | X4: 5 | Y4: 2.1 | Z4: 7.1 | AA4: 0.3 | AB4: 0.5 | AC4: 0.1 | AD4: 1.6 | AE4: 0.2 | AF4: 2.6 | AG4: 20.3 | AH4: 15.9 | AI4: 23.5 | AJ4: 32.3 | AK4: 1.8 | AL4: 54.8 | AM4: 8.8 | AN4: 11.8 | AO4: 6.6 | AP4: 3.6 | AQ4: 1.5 | AR4: 5.2 | AS4: 87.5 | AT4: 80.4 | AU4: 92.7
A5: 05004 | B5: ABRIAQUÍ | C5: 13 | D5: 6.7 | E5: 16.9 | F5: 66.8 | G5: 42.8 | H5: 81.6 | I5: 1.3 | J5: 1 | K5: 1.5 | L5: 1.9 | M5: 3.7 | N5: 0.8 | O5: 37.4 | P5: 36.4 | Q5: 38 | R5: 5.4 | S5: 5.1 | T5: 5.6 | U5: 39.6 | V5: 2.4 | W5: 62.6 | X5: 2.4 | Y5: 0.3 | Z5: 3.8 | AA5: 0.8 | AB5: 1 | AC5: 0.6 | AD5: 3.4 | AE5: 2 | AF5: 4.2 | AG5: 13.1 | AH5: 11.4 | AI5: 14.2 | AJ5: 34.4 | AK5: 2 | AL5: 54.5 | AM5: 11.7 | AN5: 15.8 | AO5: 9.2 | AP5: 1.2 | AQ5: 0.7 | AR5: 1.5 | AS5: 87.6 | AT5: 83.8 | AU5: 90
A6: 05021 | B6: ALEJANDRÍA | C6: 15.7 | D6: 11.4 | E6: 21.9 | F6: 72.9 | G6: 60.3 | H6: 91.3 | I6: 1.2 | J6: 1.2 | K6: 1.1 | L6: 0.5 | M6: 0.9 | N6: 0 | O6: 36.7 | P6: 32.8 | Q6: 42.3 | R6: 4.1 | S6: 4.9 | T6: 3 | U6: 3.7 | V6: 1.3 | W6: 7.1 | X6: 2.5 | Y6: 1.9 | Z6: 3.4 | AA6: 0.4 | AB6: 0.5 | AC6: 0.2 | AD6: 2.5 | AE6: 0.6 | AF6: 5.3 | AG6: 17.9 | AH6: 10.8 | AI6: 28.3 | AJ6: 26.8 | AK6: 0.5 | AL6: 65.3 | AM6: 11 | AN6: 11.8 | AO6: 9.8 | AP6: 1.5 | AQ6: 0.9 | AR6: 2.5 | AS6: 87.1 | AT6: 84.7 | AU6: 90.7
A7: 05030 | B7: AMAGÁ | C7: 15.4 | D7: 11 | E7: 19.5 | F7: 64.4 | G7: 52.1 | H7: 75.8 | I7: 1.3 | J7: 1.4 | K7: 1.2 | L7: 4.3 | M7: 5.1 | N7: 3.6 | O7: 27.2 | P7: 25.9 | Q7: 28.4 | R7: 4.8 | S7: 5.4 | T7: 4.2 | U7: 5.6 | V7: 1.6 | W7: 9.4 | X7: 4.7 | Y7: 5.3 | Z7: 4 | AA7: 0.3 | AB7: 0.2 | AC7: 0.4 | AD7: 1.4 | AE7: 0.2 | AF7: 2.6 | AG7: 15.7 | AH7: 13.3 | AI7: 17.9 | AJ7: 4.6 | AK7: 1 | AL7: 7.9 | AM7: 14.1 | AN7: 14.5 | AO7: 13.6 | AP7: 0.8 | AQ7: 0.6 | AR7: 0.9 | AS7: 69.5 | AT7: 69.1 | AU7: 69.9
A8: 05031 | B8: AMALFI | C8: 19.1 | D8: 14 | E8: 26.1 | F8: 73.1 | G8: 60.1 | H8: 90.9 | I8: 1.4 | J8: 1 | K8: 2 | L8: 5.2 | M8: 1.4 | N8: 10.5 | O8: 32.3 | P8: 35.9 | Q8: 27.4 | R8: 6.3 | S8: 6.4 | T8: 6.1 | U8: 32.7 | V8: 3.9 | W8: 72.5 | X8: 5.9 | Y8: 3.8 | Z8: 8.9 | AA8: 4.6 | AB8: 2.9 | AC8: 6.9 | AD8: 9.5 | AE8: 0.7 | AF8: 21.7 | AG8: 23.2 | AH8: 18.4 | AI8: 29.6 | AJ8: 36.4 | AK8: 2.4 | AL8: 83.3 | AM8: 12.1 | AN8: 12.5 | AO8: 11.5 | AP8: 3.5 | AQ8: 1.6 | AR8: 6.1 | AS8: 86.4 | AT8: 83.2 | AU8: 91
A9: 05034 | B9: ANDES | C9: 18.8 | D9: 12.8 | E9: 25.1 | F9: 72.1 | G9: 58.1 | H9: 86.7 | I9: 1.5 | J9: 1.3 | K9: 1.8 | L9: 4.7 | M9: 6.3 | N9: 3 | O9: 29.9 | P9: 29.2 | Q9: 30.5 | R9: 5 | S9: 6.2 | T9: 3.6 | U9: 33.6 | V9: 7.9 | W9: 60.6 | X9: 5.5 | Y9: 3.4 | Z9: 7.7 | AA9: 0.4 | AB9: 0.3 | AC9: 0.5 | AD9: 0.7 | AE9: 0.2 | AF9: 1.2 | AG9: 18.2 | AH9: 14.6 | AI9: 22 | AJ9: 28.3 | AK9: 1.5 | AL9: 56.3 | AM9: 12.7 | AN9: 14.2 | AO9: 11.1 | AP9: 2.6 | AQ9: 1 | AR9: 4.2 | AS9: 87.2 | AT9: 81.3 | AU9: 93.3
A10: 05036 | B10: ANGELÓPOLIS | C10: 18.4 | D10: 11.7 | E10: 23 | F10: 74.3 | G10: 62.1 | H10: 82.9 | I10: 1.4 | J10: 1.3 | K10: 1.5 | L10: 1.5 | M10: 1.6 | N10: 1.5 | O10: 29.2 | P10: 29.8 | Q10: 28.8 | R10: 5.6 | S10: 6.9 | T10: 4.6 | U10: 16.8 | V10: 6.6 | W10: 23.8 | X10: 3.9 | Y10: 2.7 | Z10: 4.7 | AA10: 1.2 | AB10: 2.5 | AC10: 0.2 | AD10: 2.3 | AE10: 2 | AF10: 2.5 | AG10: 20.6 | AH10: 15.4 | AI10: 24.1 | AJ10: 10.8 | AK10: 0.8 | AL10: 17.7 | AM10: 11.1 | AN10: 11.2 | AO10: 11 | AP10: 1.7 | AQ10: 1.1 | AR10: 2.1 | AS10: 74 | AT10: 74.5 | AU10: 73.7
A11: 05038 | B11: ANGOSTURA | C11: 25.3 | D11: 12.3 | E11: 29.8 | F11: 81.2 | G11: 58.5 | H11: 89.2 | I11: 1.9 | J11: 1.3 | K11: 2.1 | L11: 10.9 | M11: 5.8 | N11: 12.7 | O11: 38.7 | P11: 38.5 | Q11: 38.7 | R11: 7.4 | S11: 7 | T11: 7.6 | U11: 49.6 | V11: 10.5 | W11: 63.5 | X11: 6.7 | Y11: 2.4 | Z11: 8.2 | AA11: 0.3 | AB11: 0.3 | AC11: 0.2 | AD11: 10.3 | AE11: 0.8 | AF11: 13.6 | AG11: 25.8 | AH11: 17.4 | AI11: 28.7 | AJ11: 26.1 | AK11: 2.1 | AL11: 34.6 | AM11: 9.4 | AN11: 9.5 | AO11: 9.4 | AP11: 3.6 | AQ11: 1.3 | AR11: 4.4 | AS11: 87 | AT11: 80.2 | AU11: 89.4
A12: 05040 | B12: ANORÍ | C12: 19.9 | D12: 16.8 | E12: 22.8 | F12: 75.6 | G12: 63.5 | H12: 87.1 | I12: 2 | J12: 1.1 | K12: 2.7 | L12: 5.8 | M12: 4.5 | N12: 7 | O12: 38.1 | P12: 37.8 | Q12: 38.3 | R12: 8.9 | S12: 10.5 | T12: 7.4 | U12: 54.5 | V12: 21.2 | W12: 85.8 | X12: 7.7 | Y12: 5.4 | Z12: 9.9 | AA12: 3.7 | AB12: 3 | AC12: 4.3 | AD12: 8.3 | AE12: 1.9 | AF12: 14.4 | AG12: 28.2 | AH12: 24.4 | AI12: 31.9 | AJ12: 43.9 | AK12: 9.7 | AL12: 76 | AM12: 9.7 | AN12: 10.5 | AO12: 9 | AP12: 3.9 | AQ12: 2.7 | AR12: 5.1 | AS12: 89.1 | AT12: 85.9 | AU12: 92.1
A13: 05042 | B13: SANTA FÉ DE ANTIOQUIA | C13: 15.7 | D13: 10.6 | E13: 27.8 | F13: 62.1 | G13: 50.6 | H13: 89.3 | I13: 1.3 | J13: 1.2 | K13: 1.7 | L13: 1.4 | M13: 1.3 | N13: 1.4 | O13: 29.8 | P13: 28.8 | Q13: 32.2 | R13: 9.7 | S13: 10.6 | T13: 7.4 | U13: 5.9 | V13: 1.5 | W13: 16.4 | X13: 4 | Y13: 2.5 | Z13: 7.6 | AA13: 1.2 | AB13: 1.3 | AC13: 0.7 | AD13: 9.4 | AE13: 1.6 | AF13: 27.9 | AG13: 19.7 | AH13: 15.4 | AI13: 30.1 | AJ13: 9.2 | AK13: 0.7 | AL13: 29.4 | AM13: 12.7 | AN13: 14 | AO13: 9.7 | AP13: 1.3 | AQ13: 0.6 | AR13: 3 | AS13: 81.9 | AT13: 78.4 | AU13: 90.3
A14: 05044 | B14: ANZÁ | C14: 27.8 | D14: 17.4 | E14: 30.8 | F14: 83.9 | G14: 63.4 | H14: 89.6 | I14: 2.1 | J14: 2.2 | K14: 2.1 | L14: 6.7 | M14: 0.2 | N14: 8.6 | O14: 30.6 | P14: 31.8 | Q14: 30.3 | R14: 6.1 | S14: 10.1 | T14: 4.9 | U14: 35.3 | V14: 1.9 | W14: 44.7 | X14: 6.4 | Y14: 2.2 | Z14: 7.6 | AA14: 0.8 | AB14: 0.2 | AC14: 0.9 | AD14: 8.5 | AE14: 0.2 | AF14: 10.9 | AG14: 25.2 | AH14: 15.3 | AI14: 28 | AJ14: 22.1 | AK14: 0.6 | AL14: 28.2 | AM14: 8.5 | AN14: 9.7 | AO14: 8.1 | AP14: 3.8 | AQ14: 1.1 | AR14: 4.6 | AS14: 87.1 | AT14: 75.9 | AU14: 90.2
... A1091: 91001 | B1091: LETICIA | C1091: 9 | D1091: 6.7 | E1091: 18.1 | F1091: 45.1 | G1091: 38.4 | H1091: 71.2 | I1091: 4 | J1091: 3.4 | K1091: 6.5 | L1091: 5.8 | M1091: 5.5 | N1091: 6.8 | O1091: 39.2 | P1091: 34.1 | Q1091: 59 | R1091: 24 | S1091: 23.1 | T1091: 27.7 | U1091: 41.7 | V1091: 46.1 | W1091: 24.7 | X1091: 5.8 | Y1091: 5.2 | Z1091: 8.3 | AA1091: 24 | AB1091: 29.7 | AC1091: 1.8 | AD1091: 3.5 | AE1091: 2.8 | AF1091: 6 | AG1091: 25.5 | AH1091: 22.4 | AI1091: 37.4 | AJ1091: 47.8 | AK1091: 44.1 | AL1091: 62.2 | AM1091: 26.6 | AN1091: 25.5 | AO1091: 30.7 | AP1091: 1.4 | AQ1091: 1.2 | AR1091: 1.8 | AS1091: 85.3 | AT1091: 83.6 | AU1091: 91.9
A1092: 91263 | B1092: EL ENCANTO | C1092: 9.7 | D1092: -- | E1092: 9.7 | F1092: 68 | G1092: -- | H1092: 68 | I1092: 11.6 | J1092: -- | K1092: 11.6 | L1092: 2.7 | M1092: -- | N1092: 2.7 | O1092: 64.9 | P1092: -- | Q1092: 64.9 | R1092: 19.9 | S1092: -- | T1092: 19.9 | U1092: 31.2 | V1092: -- | W1092: 31.2 | X1092: 13.8 | Y1092: -- | Z1092: 13.8 | AA1092: 2.4 | AB1092: -- | AC1092: 2.4 | AD1092: 1.9 | AE1092: -- | AF1092: 1.9 | AG1092: 35.4 | AH1092: -- | AI1092: 35.4 | AJ1092: 80.9 | AK1092: -- | AL1092: 80.9 | AM1092: 42.4 | AN1092: -- | AO1092: 42.4 | AP1092: 4.8 | AQ1092: -- | AR1092: 4.8 | AS1092: 96.4 | AT1092: -- | AU1092: 96.4
A1093: 91405 | B1093: LA CHORRERA | C1093: 6.3 | D1093: -- | E1093: 6.3 | F1093: 73.9 | G1093: -- | H1093: 73.9 | I1093: 17.4 | J1093: -- | K1093: 17.4 | L1093: 11.2 | M1093: -- | N1093: 11.2 | O1093: 88.2 | P1093: -- | Q1093: 88.2 | R1093: 21 | S1093: -- | T1093: 21 | U1093: 69.6 | V1093: -- | W1093: 69.6 | X1093: 12.1 | Y1093: -- | Z1093: 12.1 | AA1093: 11.6 | AB1093: -- | AC1093: 11.6 | AD1093: 8.7 | AE1093: -- | AF1093: 8.7 | AG1093: 34.6 | AH1093: -- | AI1093: 34.6 | AJ1093: 83.3 | AK1093: -- | AL1093: 83.3 | AM1093: 54 | AN1093: -- | AO1093: 54 | AP1093: 0.2 | AQ1093: -- | AR1093: 0.2 | AS1093: 96.9 | AT1093: -- | AU1093: 96.9
A1094: 91407 | B1094: LA PEDRERA | C1094: 28.9 | D1094: -- | E1094: 28.9 | F1094: 78.1 | G1094: -- | H1094: 78.1 | I1094: 24 | J1094: -- | K1094: 24 | L1094: 6 | M1094: -- | N1094: 6 | O1094: 84.2 | P1094: -- | Q1094: 84.2 | R1094: 44.6 | S1094: -- | T1094: 44.6 | U1094: 80.1 | V1094: -- | W1094: 80.1 | X1094: 20.9 | Y1094: -- | Z1094: 20.9 | AA1094: 14.1 | AB1094: -- | AC1094: 14.1 | AD1094: 18 | AE1094: -- | AF1094: 18 | AG1094: 44.6 | AH1094: -- | AI1094: 44.6 | AJ1094: 95 | AK1094: -- | AL1094: 95 | AM1094: 63.4 | AN1094: -- | AO1094: 63.4 | AP1094: 2.1 | AQ1094: -- | AR1094: 2.1 | AS1094: 94.9 | AT1094: -- | AU1094: 94.9
A1095: 91430 | B1095: LA VICTORIA | C1095: 52.5 | D1095: -- | E1095: 52.5 | F1095: 92.5 | G1095: -- | H1095: 92.5 | I1095: 27.5 | J1095: -- | K1095: 27.5 | L1095: 12.5 | M1095: -- | N1095: 12.5 | O1095: 95 | P1095: -- | Q1095: 95 | R1095: 32.5 | S1095: -- | T1095: 32.5 | U1095: 82.5 | V1095: -- | W1095: 82.5 | X1095: 37.5 | Y1095: -- | Z1095: 37.5 | AA1095: 55 | AB1095: -- | AC1095: 55 | AD1095: 40 | AE1095: -- | AF1095: 40 | AG1095: 55 | AH1095: -- | AI1095: 55 | AJ1095: 85 | AK1095: -- | AL1095: 85 | AM1095: 50 | AN1095: -- | AO1095: 50 | AP1095: 0 | AQ1095: -- | AR1095: 0 | AS1095: 100 | AT1095: -- | AU1095: 100
A1096: 91460 | B1096: MIRITÍ - PARANÁ | C1096: 22.3 | D1096: -- | E1096: 22.3 | F1096: 83.2 | G1096: -- | H1096: 83.2 | I1096: 28.5 | J1096: -- | K1096: 28.5 | L1096: 4.5 | M1096: -- | N1096: 4.5 | O1096: 88.8 | P1096: -- | Q1096: 88.8 | R1096: 58.1 | S1096: -- | T1096: 58.1 | U1096: 86.6 | V1096: -- | W1096: 86.6 | X1096: 13.4 | Y1096: -- | Z1096: 13.4 | AA1096: 22.9 | AB1096: -- | AC1096: 22.9 | AD1096: 19 | AE1096: -- | AF1096: 19 | AG1096: 41.3 | AH1096: -- | AI1096: 41.3 | AJ1096: 95.5 | AK1096: -- | AL1096: 95.5 | AM1096: 68.7 | AN1096: -- | AO1096: 68.7 | AP1096: 1.7 | AQ1096: -- | AR1096: 1.7 | AS1096: 96.6 | AT1096: -- | AU1096: 96.6
A1097: 91530 | B1097: PUERTO ALEGRÍA | C1097: 19.8 | D1097: -- | E1097: 19.8 | F1097: 85 | G1097: -- | H1097: 85 | I1097: 19.8 | J1097: -- | K1097: 19.8 | L1097: 31.7 | M1097: -- | N1097: 31.7 | O1097: 79.6 | P1097: -- | Q1097: 79.6 | R1097: 19.8 | S1097: -- | T1097: 19.8 | U1097: 39.5 | V1097: -- | W1097: 39.5 | X1097: 11.4 | Y1097: -- | Z1097: 11.4 | AA1097: 0 | AB1097: -- | AC1097: 0 | AD1097: 4.8 | AE1097: -- | AF1097: 4.8 | AG1097: 44.3 | AH1097: -- | AI1097: 44.3 | AJ1097: 73.7 | AK1097: -- | AL1097: 73.7 | AM1097: 41.3 | AN1097: -- | AO1097: 41.3 | AP1097: 1.8 | AQ1097: -- | AR1097: 1.8 | AS1097: 92.8 | AT1097: -- | AU1097: 92.8
A1098: 91536 | B1098: PUERTO ARICA | C1098: 15.4 | D1098: -- | E1098: 15.4 | F1098: 80.8 | G1098: -- | H1098: 80.8 | I1098: 14.5 | J1098: -- | K1098: 14.5 | L1098: 17.8 | M1098: -- | N1098: 17.8 | O1098: 74.8 | P1098: -- | Q1098: 74.8 | R1098: 17.8 | S1098: -- | T1098: 17.8 | U1098: 29.4 | V1098: -- | W1098: 29.4 | X1098: 16.8 | Y1098: -- | Z1098: 16.8 | AA1098: 1.4 | AB1098: -- | AC1098: 1.4 | AD1098: 7.9 | AE1098: -- | AF1098: 7.9 | AG1098: 40.2 | AH1098: -- | AI1098: 40.2 | AJ1098: 87.4 | AK1098: -- | AL1098: 87.4 | AM1098: 34.6 | AN1098: -- | AO1098: 34.6 | AP1098: 0.9 | AQ1098: -- | AR1098: 0.9 | AS1098: 96.7 | AT1098: -- | AU1098: 96.7
A1099: 91540 | B1099: PUERTO NARIÑO | C1099: 17.7 | D1099: 9.1 | E1099: 22.7 | F1099: 64.6 | G1099: 45.4 | H1099: 76.1 | I1099: 6 | J1099: 5.7 | K1099: 6.1 | L1099: 5.2 | M1099: 2.4 | N1099: 6.8 | O1099: 63.5 | P1099: 51.5 | Q1099: 70.6 | R1099: 20.7 | S1099: 13.8 | T1099: 24.8 | U1099: 46.8 | V1099: 43.6 | W1099: 48.8 | X1099: 13.4 | Y1099: 6.6 | Z1099: 17.5 | AA1099: 33.6 | AB1099: 88.3 | AC1099: 1.2 | AD1099: 4.3 | AE1099: 3.3 | AF1099: 5 | AG1099: 36.5 | AH1099: 23.1 | AI1099: 44.5 | AJ1099: 61 | AK1099: 26.3 | AL1099: 81.6 | AM1099: 26.4 | AN1099: 28 | AO1099: 25.4 | AP1099: 5.4 | AQ1099: 0.9 | AR1099: 8.1 | AS1099: 90.8 | AT1099: 84.6 | AU1099: 94.5
A1100: 91669 | B1100: PUERTO SANTANDER | C1100: 17.6 | D1100: -- | E1100: 17.6 | F1100: 80.4 | G1100: -- | H1100: 80.4 | I1100: 19.9 | J1100: -- | K1100: 19.9 | L1100: 18.9 | M1100: -- | N1100: 18.9 | O1100: 77.7 | P1100: -- | Q1100: 77.7 | R1100: 22.3 | S1100: -- | T1100: 22.3 | U1100: 52.8 | V1100: -- | W1100: 52.8 | X1100: 10.3 | Y1100: -- | Z1100: 10.3 | AA1100: 1.3 | AB1100: -- | AC1100: 1.3 | AD1100: 7 | AE1100: -- | AF1100: 7 | AG1100: 40.5 | AH1100: -- | AI1100: 40.5 | AJ1100: 80.4 | AK1100: -- | AL1100: 80.4 | AM1100: 61.1 | AN1100: -- | AO1100: 61.1 | AP1100: 1.7 | AQ1100: -- | AR1100: 1.7 | AS1100: 96.7 | AT1100: -- | AU1100: 96.7
A1101: 91798 | B1101: TARAPACÁ | C1101: 22.2 | D1101: -- | E1101: 22.2 | F1101: 72.2 | G1101: -- | H1101: 72.2 | I1101: 13.4 | J1101: -- | K1101: 13.4 | L1101: 2.7 | M1101: -- | N1101: 2.7 | O1101: 78.9 | P1101: -- | Q1101: 78.9 | R1101: 20.6 | S1101: -- | T1101: 20.6 | U1101: 48.9 | V1101: -- | W1101: 48.9 | X1101: 10 | Y1101: -- | Z1101: 10 | AA1101: 0.7 | AB1101: -- | AC1101: 0.7 | AD1101: 12.3 | AE1101: -- | AF1101: 12.3 | AG1101: 40.1 | AH1101: -- | AI1101: 40.1 | AJ1101: 90.8 | AK1101: -- | AL1101: 90.8 | AM1101: 41.1 | AN1101: -- | AO1101: 41.1 | AP1101: 0.6 | AQ1101: -- | AR1101: 0.6 | AS1101: 95.5 | AT1101: -- | AU1101: 95.5
A1102: 94001 | B1102: INÍRIDA | C1102: 15.8 | D1102: 12.1 | E1102: 25.8 | F1102: 63.8 | G1102: 55.5 | H1102: 86 | I1102: 6 | J1102: 4.4 | K1102: 10.3 | L1102: 8.8 | M1102: 8.9 | N1102: 8.4 | O1102: 52.2 | P1102: 45.3 | Q1102: 70.4 | R1102: 24.5 | S1102: 24.1 | T1102: 25.6 | U1102: 58.5 | V1102: 54.3 | W1102: 69.6 | X1102: 8.4 | Y1102: 6.9 | Z1102: 12.3 | AA1102: 31.9 | AB1102: 36.3 | AC1102: 20.1 | AD1102: 33 | AE1102: 20.4 | AF1102: 66.8 | AG1102: 35.5 | AH1102: 31.9 | AI1102: 45 | AJ1102: 69.9 | AK1102: 66.7 | AL1102: 78.2 | AM1102: 21.8 | AN1102: 19.9 | AO1102: 26.9 | AP1102: 1 | AQ1102: 0.8 | AR1102: 1.4 | AS1102: 87.6 | AT1102: 84.5 | AU1102: 96
A1103: 94343 | B1103: BARRANCOMINAS | C1103: 25.5 | D1103: -- | E1103: 25.5 | F1103: 82.9 | G1103: -- | H1103: 82.9 | I1103: 20.9 | J1103: -- | K1103: 20.9 | L1103: 2.8 | M1103: -- | N1103: 2.8 | O1103: 79.8 | P1103: -- | Q1103: 79.8 | R1103: 34.7 | S1103: -- | T1103: 34.7 | U1103: 66.9 | V1103: -- | W1103: 66.9 | X1103: 10 | Y1103: -- | Z1103: 10 | AA1103: 22.3 | AB1103: -- | AC1103: 22.3 | AD1103: 44.3 | AE1103: -- | AF1103: 44.3 | AG1103: 53.4 | AH1103: -- | AI1103: 53.4 | AJ1103: 75 | AK1103: -- | AL1103: 75 | AM1103: 27.8 | AN1103: -- | AO1103: 27.8 | AP1103: 1.7 | AQ1103: -- | AR1103: 1.7 | AS1103: 93.4 | AT1103: -- | AU1103: 93.4
A1104: 94663 | B1104: MAPIRIPANA | C1104: 39.6 | D1104: -- | E1104: 39.6 | F1104: 89.6 | G1104: -- | H1104: 89.6 | I1104: 18.7 | J1104: -- | K1104: 18.7 | L1104: 0.7 | M1104: -- | N1104: 0.7 | O1104: 92.5 | P1104: -- | Q1104: 92.5 | R1104: 32.8 | S1104: -- | T1104: 32.8 | U1104: 57.5 | V1104: -- | W1104: 57.5 | X1104: 18.7 | Y1104: -- | Z1104: 18.7 | AA1104: 18.7 | AB1104: -- | AC1104: 18.7 | AD1104: 22.4 | AE1104: -- | AF1104: 22.4 | AG1104: 59 | AH1104: -- | AI1104: 59 | AJ1104: 78.4 | AK1104: -- | AL1104: 78.4 | AM1104: 30.6 | AN1104: -- | AO1104: 30.6 | AP1104: 0 | AQ1104: -- | AR1104: 0 | AS1104: 98.5 | AT1104: -- | AU1104: 98.5
A1105: 94883 | B1105: SAN FELIPE | C1105: 23 | D1105: -- | E1105: 23 | F1105: 86.1 | G1105: -- | H1105: 86.1 | I1105: 19.3 | J1105: -- | K1105: 19.3 | L1105: 3.3 | M1105: -- | N1105: 3.3 | O1105: 67.9 | P1105: -- | Q1105: 67.9 | R1105: 26.6 | S1105: -- | T1105: 26.6 | U1105: 84.3 | V1105: -- | W1105: 84.3 | X1105: 16.4 | Y1105: -- | Z1105: 16.4 | AA1105: 1.8 | AB1105: -- | AC1105: 1.8 | AD1105: 66.8 | AE1105: -- | AF1105: 66.8 | AG1105: 43.8 | AH1105: -- | AI1105: 43.8 | AJ1105: 93.8 | AK1105: -- | AL1105: 93.8 | AM1105: 47.8 | AN1105: -- | AO1105: 47.8 | AP1105: 2.6 | AQ1105: -- | AR1105: 2.6 | AS1105: 97.8 | AT1105: -- | AU1105: 97.8
A1106: 94884 | B1106: PUERTO COLOMBIA | C1106: 30.7 | D1106: -- | E1106: 30.7 | F1106: 96.2 | G1106: -- | H1106: 96.2 | I1106: 21.1 | J1106: -- | K1106: 21.1 | L1106: 7 | M1106: -- | N1106: 7 | O1106: 85.6 | P1106: -- | Q1106: 85.6 | R1106: 27.5 | S1106: -- | T1106: 27.5 | U1106: 97.1 | V1106: -- | W1106: 97.1 | X1106: 12.5 | Y1106: -- | Z1106: 12.5 | AA1106: 1.9 | AB1106: -- | AC1106: 1.9 | AD1106: 77 | AE1106: -- | AF1106: 77 | AG1106: 43.5 | AH1106: -- | AI1106: 43.5 | AJ1106: 95.8 | AK1106: -- | AL1106: 95.8 | AM1106: 53 | AN1106: -- | AO1106: 53 | AP1106: 0.6 | AQ1106: -- | AR1106: 0.6 | AS1106: 99.4 | AT1106: -- | AU1106: 99.4
A1107: 94885 | B1107: LA GUADALUPE | C1107: 17.1 | D1107: -- | E1107: 17.1 | F1107: 87.8 | G1107: -- | H1107: 87.8 | I1107: 24.4 | J1107: -- | K1107: 24.4 | L1107: 2.4 | M1107: -- | N1107: 2.4 | O1107: 53.7 | P1107: -- | Q1107: 53.7 | R1107: 29.3 | S1107: -- | T1107: 29.3 | U1107: 87.8 | V1107: -- | W1107: 87.8 | X1107: 19.5 | Y1107: -- | Z1107: 19.5 | AA1107: 0 | AB1107: -- | AC1107: 0 | AD1107: 65.9 | AE1107: -- | AF1107: 65.9 | AG1107: 39 | AH1107: -- | AI1107: 39 | AJ1107: 80.5 | AK1107: -- | AL1107: 80.5 | AM1107: 48.8 | AN1107: -- | AO1107: 48.8 | AP1107: 4.9 | AQ1107: -- | AR1107: 4.9 | AS1107: 95.1 | AT1107: -- | AU1107: 95.1
A1108: 94886 | B1108: CACAHUAL | C1108: 35.6 | D1108: -- | E1108: 35.6 | F1108: 90.2 | G1108: -- | H1108: 90.2 | I1108: 10.6 | J1108: -- | K1108: 10.6 | L1108: 4.5 | M1108: -- | N1108: 4.5 | O1108: 58.3 | P1108: -- | Q1108: 58.3 | R1108: 40.2 | S1108: -- | T1108: 40.2 | U1108: 63.6 | V1108: -- | W1108: 63.6 | X1108: 23.5 | Y1108: -- | Z1108: 23.5 | AA1108: 10.6 | AB1108: -- | AC1108: 10.6 | AD1108: 53.8 | AE1108: -- | AF1108: 53.8 | AG1108: 53.8 | AH1108: -- | AI1108: 53.8 | AJ1108: 87.9 | AK1108: -- | AL1108: 87.9 | AM1108: 32.6 | AN1108: -- | AO1108: 32.6 | AP1108: 10.6 | AQ1108: -- | AR1108: 10.6 | AS1108: 98.5 | AT1108: -- | AU1108: 98.5
A1109: 94887 | B1109: PANA PANA | C1109: 28.3 | D1109: -- | E1109: 28.3 | F1109: 96.2 | G1109: -- | H1109: 96.2 | I1109: 34.6 | J1109: -- | K1109: 34.6 | L1109: 16 | M1109: -- | N1109: 16 | O1109: 96.2 | P1109: -- | Q1109: 96.2 | R1109: 32.1 | S1109: -- | T1109: 32.1 | U1109: 94.9 | V1109: -- | W1109: 94.9 | X1109: 34.2 | Y1109: -- | Z1109: 34.2 | AA1109: 2.1 | AB1109: -- | AC1109: 2.1 | AD1109: 86.1 | AE1109: -- | AF1109: 86.1 | AG1109: 52.3 | AH1109: -- | AI1109: 52.3 | AJ1109: 89.9 | AK1109: -- | AL1109: 89.9 | AM1109: 56.1 | AN1109: -- | AO1109: 56.1 | AP1109: 0.4 | AQ1109: -- | AR1109: 0.4 | AS1109: 98.3 | AT1109: -- | AU1109: 98.3
A1110: 94888 | B1110: MORICHAL | C1110: 43.2 | D1110: -- | E1110: 43.2 | F1110: 96.2 | G1110: -- | H1110: 96.2 | I1110: 15.2 | J1110: -- | K1110: 15.2 | L1110: 14.4 | M1110: -- | N1110: 14.4 | O1110: 93.9 | P1110: -- | Q1110: 93.9 | R1110: 46.2 | S1110: -- | T1110: 46.2 | U1110: 80.3 | V1110: -- | W1110: 80.3 | X1110: 23.5 | Y1110: -- | Z1110: 23.5 | AA1110: 3 | AB1110: -- | AC1110: 3 | AD1110: 63.6 | AE1110: -- | AF1110: 63.6 | AG1110: 62.1 | AH1110: -- | AI1110: 62.1 | AJ1110: 95.5 | AK1110: -- | AL1110: 95.5 | AM1110: 41.7 | AN1110: -- | AO1110: 41.7 | AP1110: 0 | AQ1110: -- | AR1110: 0 | AS1110: 98.5 | AT1110: -- | AU1110: 98.5
A1111: 95001 | B1111: SAN JOSÉ DEL GUAVIARE | C1111: 10.7 | D1111: 7.7 | E1111: 19.9 | F1111: 55.8 | G1111: 46.2 | H1111: 84.7 | I1111: 3.1 | J1111: 2.2 | K1111: 5.9 | L1111: 10.4 | M1111: 10.8 | N1111: 9.4 | O1111: 33.1 | P1111: 31 | Q1111: 39.5 | R1111: 10.7 | S1111: 11.2 | T1111: 9.1 | U1111: 28.9 | V1111: 25 | W1111: 40.6 | X1111: 4.9 | Y1111: 3.6 | Z1111: 9 | AA1111: 10.9 | AB1111: 11.8 | AC1111: 8.2 | AD1111: 11.9 | AE1111: 5.1 | AF1111: 32.3 | AG1111: 20.2 | AH1111: 18.4 | AI1111: 25.9 | AJ1111: 40.4 | AK1111: 32.6 | AL1111: 63.7 | AM1111: 20.6 | AN1111: 19.8 | AO1111: 23.2 | AP1111: 1.9 | AQ1111: 1.5 | AR1111: 3.2 | AS1111: 86.2 | AT1111: 83.5 | AU1111: 94.5
A1112: 95015 | B1112: CALAMAR | C1112: 13.1 | D1112: 11 | E1112: 15.2 | F1112: 77.6 | G1112: 65.1 | H1112: 89.7 | I1112: 2.9 | J1112: 2.6 | K1112: 3.2 | L1112: 4.2 | M1112: 5.4 | N1112: 3.1 | O1112: 31.3 | P1112: 36 | Q1112: 26.8 | R1112: 8.6 | S1112: 13 | T1112: 4.3 | U1112: 51 | V1112: 50.9 | W1112: 51.1 | X1112: 6.9 | Y1112: 4.8 | Z1112: 8.8 | AA1112: 39.6 | AB1112: 75.4 | AC1112: 4.9 | AD1112: 25.6 | AE1112: 24.6 | AF1112: 26.6 | AG1112: 21.9 | AH1112: 20.3 | AI1112: 23.4 | AJ1112: 64.9 | AK1112: 55.2 | AL1112: 74.4 | AM1112: 16.7 | AN1112: 16.3 | AO1112: 17 | AP1112: 4.7 | AQ1112: 3 | AR1112: 6.3 | AS1112: 92.7 | AT1112: 88.6 | AU1112: 96.7
A1113: 95025 | B1113: EL RETORNO | C1113: 14.5 | D1113: 8.8 | E1113: 17.1 | F1113: 74.8 | G1113: 52.6 | H1113: 85.3 | I1113: 2.7 | J1113: 1.7 | K1113: 3.2 | L1113: 6.6 | M1113: 6.7 | N1113: 6.6 | O1113: 39.1 | P1113: 33.2 | Q1113: 41.9 | R1113: 6.3 | S1113: 10 | T1113: 4.6 | U1113: 30.3 | V1113: 10.2 | W1113: 39.8 | X1113: 5.7 | Y1113: 3.4 | Z1113: 6.8 | AA1113: 12.7 | AB1113: 35.8 | AC1113: 1.8 | AD1113: 15.4 | AE1113: 5.4 | AF1113: 20.2 | AG1113: 23.5 | AH1113: 20 | AI1113: 25.2 | AJ1113: 43.9 | AK1113: 4.2 | AL1113: 62.6 | AM1113: 17.4 | AN1113: 19.1 | AO1113: 16.6 | AP1113: 2.5 | AQ1113: 1.9 | AR1113: 2.8 | AS1113: 91 | AT1113: 82.5 | AU1113: 95
A1114: 95200 | B1114: MIRAFLORES | C1114: 16.4 | D1114: 10.5 | E1114: 19.4 | F1114: 81.3 | G1114: 60.3 | H1114: 92 | I1114: 4.5 | J1114: 3 | K1114: 5.3 | L1114: 8.6 | M1114: 5.9 | N1114: 10 | O1114: 48.3 | P1114: 45.8 | Q1114: 49.5 | R1114: 7.5 | S1114: 10.2 | T1114: 6.1 | U1114: 66.1 | V1114: 92.2 | W1114: 52.8 | X1114: 4.7 | Y1114: 2.6 | Z1114: 5.7 | AA1114: 28.2 | AB1114: 78.9 | AC1114: 2.4 | AD1114: 3.5 | AE1114: 3.1 | AF1114: 3.8 | AG1114: 19.9 | AH1114: 20.1 | AI1114: 19.8 | AJ1114: 60.9 | AK1114: 24 | AL1114: 79.6 | AM1114: 19.6 | AN1114: 17.2 | AO1114: 20.8 | AP1114: 1.7 | AQ1114: 1.5 | AR1114: 1.8 | AS1114: 92.5 | AT1114: 83.2 | AU1114: 97.2
A1115: 97001 | B1115: MITÚ | C1115: 18.7 | D1115: 7.2 | E1115: 27.5 | F1115: 62.7 | G1115: 36.8 | H1115: 82.5 | I1115: 11.5 | J1115: 3 | K1115: 17.9 | L1115: 8.5 | M1115: 6.9 | N1115: 9.7 | O1115: 68.9 | P1115: 42.2 | Q1115: 89.5 | R1115: 29 | S1115: 15.1 | T1115: 39.6 | U1115: 56 | V1115: 21 | W1115: 83 | X1115: 9.5 | Y1115: 4 | Z1115: 13.7 | AA1115: 33.5 | AB1115: 54.1 | AC1115: 17.7 | AD1115: 32.3 | AE1115: 14.3 | AF1115: 46 | AG1115: 36.7 | AH1115: 21 | AI1115: 48.8 | AJ1115: 58.7 | AK1115: 13.8 | AL1115: 93.2 | AM1115: 35.7 | AN1115: 27.4 | AO1115: 42.1 | AP1115: 0.8 | AQ1115: 0.8 | AR1115: 0.7 | AS1115: 88.2 | AT1115: 78.5 | AU1115: 95.6
A1116: 97161 | B1116: CARURÚ | C1116: 21.8 | D1116: 13 | E1116: 29.3 | F1116: 73.9 | G1116: 54.3 | H1116: 90.7 | I1116: 7.3 | J1116: 3.6 | K1116: 10.3 | L1116: 11.2 | M1116: 8.1 | N1116: 13.8 | O1116: 79.1 | P1116: 59.1 | Q1116: 96.2 | R1116: 25.3 | S1116: 17.8 | T1116: 31.7 | U1116: 30.9 | V1116: 9.3 | W1116: 49.3 | X1116: 11.2 | Y1116: 4.9 | Z1116: 16.6 | AA1116: 38.4 | AB1116: 78.9 | AC1116: 3.8 | AD1116: 6.7 | AE1116: 3.6 | AF1116: 9.3 | AG1116: 33.9 | AH1116: 23.9 | AI1116: 42.4 | AJ1116: 54.4 | AK1116: 9.3 | AL1116: 92.8 | AM1116: 30 | AN1116: 23.5 | AO1116: 35.5 | AP1116: 0 | AQ1116: 0 | AR1116: 0 | AS1116: 89.4 | AT1116: 78.9 | AU1116: 98.3
...

Sheet TB_REF
A1: ID | B1: Departamento | C1: ID_Depto | D1: #Mpios | F1: ID1_Dpto | G1: ID1_Mpio | H1: Municipio | I1: ID_Mpio
A2: 05 | B2: ANTIOQUIA | C2: =+A2&" - "&B2 -> 05 - ANTIOQUIA | D2: =+COUNTIF($F:$F,LEFT(C2,2)) -> 125 | F2: 05 | G2: 05001 | H2: MEDELLÍN | I2: =+G2&" - "&H2 -> 05001 - MEDELLÍN
A3: 08 | B3: ATLÁNTICO | C3: =+A3&" - "&B3 -> 08 - ATLÁNTICO | D3: =+COUNTIF($F:$F,LEFT(C3,2)) -> 23 | F3: 05 | G3: 05002 | H3: ABEJORRAL | I3: =+G3&" - "&H3 -> 05002 - ABEJORRAL
A4: 11 | B4: BOGOTÁ, D.C. | C4: =+A4&" - "&B4 -> 11 - BOGOTÁ, D.C. | D4: =+COUNTIF($F:$F,LEFT(C4,2)) -> 1 | F4: 05 | G4: 05004 | H4: ABRIAQUÍ | I4: =+G4&" - "&H4 -> 05004 - ABRIAQUÍ
A5: 13 | B5: BOLÍVAR | C5: =+A5&" - "&B5 -> 13 - BOLÍVAR | D5: =+COUNTIF($F:$F,LEFT(C5,2)) -> 46 | F5: 05 | G5: 05021 | H5: ALEJANDRÍA | I5: =+G5&" - "&H5 -> 05021 - ALEJANDRÍA
A6: 15 | B6: BOYACÁ | C6: =+A6&" - "&B6 -> 15 - BOYACÁ | D6: =+COUNTIF($F:$F,LEFT(C6,2)) -> 123 | F6: 05 | G6: 05030 | H6: AMAGÁ | I6: =+G6&" - "&H6 -> 05030 - AMAGÁ
A7: 17 | B7: CALDAS | C7: =+A7&" - "&B7 -> 17 - CALDAS | D7: =+COUNTIF($F:$F,LEFT(C7,2)) -> 27 | F7: 05 | G7: 05031 | H7: AMALFI | I7: =+G7&" - "&H7 -> 05031 - AMALFI
A8: 18 | B8: CAQUETÁ | C8: =+A8&" - "&B8 -> 18 - CAQUETÁ | D8: =+COUNTIF($F:$F,LEFT(C8,2)) -> 16 | F8: 05 | G8: 05034 | H8: ANDES | I8: =+G8&" - "&H8 -> 05034 - ANDES
A9: 19 | B9: CAUCA | C9: =+A9&" - "&B9 -> 19 - CAUCA | D9: =+COUNTIF($F:$F,LEFT(C9,2)) -> 42 | F9: 05 | G9: 05036 | H9: ANGELÓPOLIS | I9: =+G9&" - "&H9 -> 05036 - ANGELÓPOLIS
A10: 20 | B10: CESAR | C10: =+A10&" - "&B10 -> 20 - CESAR | D10: =+COUNTIF($F:$F,LEFT(C10,2)) -> 25 | F10: 05 | G10: 05038 | H10: ANGOSTURA | I10: =+G10&" - "&H10 -> 05038 - ANGOSTURA
A11: 23 | B11: CÓRDOBA | C11: =+A11&" - "&B11 -> 23 - CÓRDOBA | D11: =+COUNTIF($F:$F,LEFT(C11,2)) -> 30 | F11: 05 | G11: 05040 | H11: ANORÍ | I11: =+G11&" - "&H11 -> 05040 - ANORÍ
A12: 25 | B12: CUNDINAMARCA | C12: =+A12&" - "&B12 -> 25 - CUNDINAMARCA | D12: =+COUNTIF($F:$F,LEFT(C12,2)) -> 116 | F12: 05 | G12: 05042 | H12: SANTA FÉ DE ANTIOQUIA | I12: =+G12&" - "&H12 -> 05042 - SANTA FÉ DE ANTIOQUIA
A13: 27 | B13: CHOCÓ | C13: =+A13&" - "&B13 -> 27 - CHOCÓ | D13: =+COUNTIF($F:$F,LEFT(C13,2)) -> 30 | F13: 05 | G13: 05044 | H13: ANZÁ | I13: =+G13&" - "&H13 -> 05044 - ANZÁ
... A34: 99 | B34: VICHADA | C34: =+A34&" - "&B34 -> 99 - VICHADA | D34: =+COUNTIF($F:$F,LEFT(C34,2)) -> 4 | F34: 05 | G34: 05148 | H34: EL CARMEN DE VIBORAL | I34: =+G34&" - "&H34 -> 05148 - EL CARMEN DE VIBORAL
F35: 05 | G35: 05150 | H35: CAROLINA | I35: =+G35&" - "&H35 -> 05150 - CAROLINA
F36: 05 | G36: 05154 | H36: CAUCASIA | I36: =+G36&" - "&H36 -> 05154 - CAUCASIA
F37: 05 | G37: 05172 | H37: CHIGORODÓ | I37: =+G37&" - "&H37 -> 05172 - CHIGORODÓ
F38: 05 | G38: 05190 | H38: CISNEROS | I38: =+G38&" - "&H38 -> 05190 - CISNEROS
F39: 05 | G39: 05197 | H39: COCORNÁ | I39: =+G39&" - "&H39 -> 05197 - COCORNÁ
F40: 05 | G40: 05206 | H40: CONCEPCIÓN | I40: =+G40&" - "&H40 -> 05206 - CONCEPCIÓN
F41: 05 | G41: 05209 | H41: CONCORDIA | I41: =+G41&" - "&H41 -> 05209 - CONCORDIA
F42: 05 | G42: 05212 | H42: COPACABANA | I42: =+G42&" - "&H42 -> 05212 - COPACABANA
F43: 05 | G43: 05234 | H43: DABEIBA | I43: =+G43&" - "&H43 -> 05234 - DABEIBA
F44: 05 | G44: 05237 | H44: DONMATÍAS | I44: =+G44&" - "&H44 -> 05237 - DONMATÍAS
F45: 05 | G45: 05240 | H45: EBÉJICO | I45: =+G45&" - "&H45 -> 05240 - EBÉJICO
F46: 05 | G46: 05250 | H46: EL BAGRE | I46: =+G46&" - "&H46 -> 05250 - EL BAGRE
... F1123: 99 | G1123: 99773 | H1123: CUMARIBO | I1123: =+G1123&" - "&H1123 -> 99773 - CUMARIBO

Sheet Visor
C7: MEDIDA DE POBREZA MULTIDIMENSIONAL MUNICIPAL - CENSO NACIONAL DE POBLACIÓN Y VIVIENDA
C8: INSTRUCCIONES DE USO PARA ACTUALIZAR LA INFORMACIÓN Para la información municipal debe: *En la casilla "Departamento" seleccionar el Departamento al que pertenece el municipio de interés. *En la casilla "Municipio" se desplegan los municipios que pertenecen al departamento previamente seleccionado, allí podrá buscar el municipio que desea analizar. Notas: El cálculo de las variables se realizó con base en los hogares particulares efectivamente censados. Tenga en cuenta la omisión censal de cada municipio al momento de realizar análisis de la información.
C9: Para la información municipal debe:
C10: *En la casilla "Departamento" seleccionar el Departamento al que pertenece el municipio de interés
C11: *En la casilla "Municipio" se desplegan los municipios que pertenecen al departamento previamente
C12: seleccionado, allí podrá buscar el municipio que desea analizar.
C13: Notas: El cálculo de las variables se realizó con base en los hogares efectivamente censados.
C14: Tenga en cuenta la omisión censal de cada municipio al momento de realizar análisis de la información.
C17: Departamento | D17: 11 - BOGOTÁ, D.C.
C18: Municipio | D18: 11001 - BOGOTÁ, D.C.
C20: Medida de Pobreza Multidimensional Municipal Principales dominios
C22: Dominio | D22: =+MID($D$18,9,100) -> BOGOTÁ, D.C.
C23: Total | D23: =+VLOOKUP(LEFT($D$18,5),'4_IPM Mpio dominios'!A:E,3,) -> 9
C24: Cabeceras | D24: =+VLOOKUP(LEFT($D$18,5),'4_IPM Mpio dominios'!A:E,4,) -> 8.9
C25: Centros poblados y rural disperso | D25: =+VLOOKUP(LEFT($D$18,5),'4_IPM Mpio dominios'!A:E,5,) -> 31.5
C26: Fuente: Censo Nacional de Población y Vivienda (CNPV 2018)
C27: Fecha de publicación: 31 de enero de 2020
C45: Fuente: Censo Nacional de Población y Vivienda (CNPV 2018)
C47: Privaciones por hogar según variable Principales dominios Municipio
C50: Privaciones por variable | D50: =+MID($D$18,9,100) -> BOGOTÁ, D.C.
D51: Total | E51: Cabeceras | F51: Centros poblados y rural disperso
C52: Analfabetismo | D52: =+VLOOKUP(LEFT($D$18,5),'8_Privaciones Mpio dominio'!A:AU,3,FALSE) -> 2.8 | E52: =+VLOOKUP(LEFT($D$18,5),'8_Privaciones Mpio dominio'!A:AU,4,FALSE) -> 2.8 | F52: =+VLOOKUP(LEFT($D$18,5),'8_Privaciones Mpio dominio'!A:AU,5,FALSE) -> 10
C53: Bajo logro educativo | D53: =+VLOOKUP(LEFT($D$18,5),'8_Privaciones Mpio dominio'!A:AU,6,FALSE) -> 26.2 | E53: =+VLOOKUP(LEFT($D$18,5),'8_Privaciones Mpio dominio'!A:AU,7,FALSE) -> 26.1 | F53: =+VLOOKUP(LEFT($D$18,5),'8_Privaciones Mpio dominio'!A:AU,8,FALSE) -> 62.5
C54: Barreras a servicios para cuidado de la primera infancia | D54: =+VLOOKUP(LEFT($D$18,5),'8_Privaciones Mpio dominio'!A:AU,9,FALSE) -> 1.8 | E54: =+VLOOKUP(LEFT($D$18,5),'8_Privaciones Mpio dominio'!A:AU,10,FALSE) -> 1.7 | F54: =+VLOOKUP(LEFT($D$18,5),'8_Privaciones Mpio dominio'!A:AU,11,FALSE) -> 3
C55: Barreras de acceso a servicios de salud | D55: =+VLOOKUP(LEFT($D$18,5),'8_Privaciones Mpio dominio'!A:AU,12,FALSE) -> 4.3 | E55: =+VLOOKUP(LEFT($D$18,5),'8_Privaciones Mpio dominio'!A:AU,13,FALSE) -> 4.3 | F55: =+VLOOKUP(LEFT($D$18,5),'8_Privaciones Mpio dominio'!A:AU,14,FALSE) -> 6
C56: Tasa de dependencia | D56: =+VLOOKUP(LEFT($D$18,5),'8_Privaciones Mpio dominio'!A:AU,15,FALSE) -> 18.9 | E56: =+VLOOKUP(LEFT($D$18,5),'8_Privaciones Mpio dominio'!A:AU,16,FALSE) -> 18.9 | F56: =+VLOOKUP(LEFT($D$18,5),'8_Privaciones Mpio dominio'!A:AU,17,FALSE) -> 35
C57: Hacinamiento crítico | D57: =+VLOOKUP(LEFT($D$18,5),'8_Privaciones Mpio dominio'!A:AU,18,FALSE) -> 5.6 | E57: =+VLOOKUP(LEFT($D$18,5),'8_Privaciones Mpio dominio'!A:AU,19,FALSE) -> 5.6 | F57: =+VLOOKUP(LEFT($D$18,5),'8_Privaciones Mpio dominio'!A:AU,20,FALSE) -> 5.5
C58: Inadecuada eliminación de excretas | D58: =+VLOOKUP(LEFT($D$18,5),'8_Privaciones Mpio dominio'!A:AU,21,FALSE) -> 0.7 | E58: =+VLOOKUP(LEFT($D$18,5),'8_Privaciones Mpio dominio'!A:AU,22,FALSE) -> 0.7 | F58: =+VLOOKUP(LEFT($D$18,5),'8_Privaciones Mpio dominio'!A:AU,23,FALSE) -> 11.8
C59: Inasistencia escolar | D59: =+VLOOKUP(LEFT($D$18,5),'8_Privaciones Mpio dominio'!A:AU,24,FALSE) -> 1.9 | E59: =+VLOOKUP(LEFT($D$18,5),'8_Privaciones Mpio dominio'!A:AU,25,FALSE) -> 1.9 | F59: =+VLOOKUP(LEFT($D$18,5),'8_Privaciones Mpio dominio'!A:AU,26,FALSE) -> 3.2
C60: Material inadecuado de paredes exteriores | D60: =+VLOOKUP(LEFT($D$18,5),'8_Privaciones Mpio dominio'!A:AU,27,FALSE) -> 0.3 | E60: =+VLOOKUP(LEFT($D$18,5),'8_Privaciones Mpio dominio'!A:AU,28,FALSE) -> 0.3 | F60: =+VLOOKUP(LEFT($D$18,5),'8_Privaciones Mpio dominio'!A:AU,29,FALSE) -> 2.3
C61: Material inadecuado de pisos | D61: =+VLOOKUP(LEFT($D$18,5),'8_Privaciones Mpio dominio'!A:AU,30,FALSE) -> 0.3 | E61: =+VLOOKUP(LEFT($D$18,5),'8_Privaciones Mpio dominio'!A:AU,31,FALSE) -> 0.3 | F61: =+VLOOKUP(LEFT($D$18,5),'8_Privaciones Mpio dominio'!A:AU,32,FALSE) -> 3.5
C62: Rezago escolar | D62: =+VLOOKUP(LEFT($D$18,5),'8_Privaciones Mpio dominio'!A:AU,33,FALSE) -> 11.5 | E62: =+VLOOKUP(LEFT($D$18,5),'8_Privaciones Mpio dominio'!A:AU,34,FALSE) -> 11.5 | F62: =+VLOOKUP(LEFT($D$18,5),'8_Privaciones Mpio dominio'!A:AU,35,FALSE) -> 16.8
C63: Sin acceso a fuente de agua mejorada | D63: =+VLOOKUP(LEFT($D$18,5),'8_Privaciones Mpio dominio'!A:AU,36,FALSE) -> 0.5 | E63: =+VLOOKUP(LEFT($D$18,5),'8_Privaciones Mpio dominio'!A:AU,37,FALSE) -> 0.5 | F63: =+VLOOKUP(LEFT($D$18,5),'8_Privaciones Mpio dominio'!A:AU,38,FALSE) -> 16.8
C64: Sin aseguramiento en salud | D64: =+VLOOKUP(LEFT($D$18,5),'8_Privaciones Mpio dominio'!A:AU,39,FALSE) -> 18.7 | E64: =+VLOOKUP(LEFT($D$18,5),'8_Privaciones Mpio dominio'!A:AU,40,FALSE) -> 18.7 | F64: =+VLOOKUP(LEFT($D$18,5),'8_Privaciones Mpio dominio'!A:AU,41,FALSE) -> 18.5
C65: Trabajo infantil | D65: =+VLOOKUP(LEFT($D$18,5),'8_Privaciones Mpio dominio'!A:AU,42,FALSE) -> 0.5 | E65: =+VLOOKUP(LEFT($D$18,5),'8_Privaciones Mpio dominio'!A:AU,43,FALSE) -> 0.5 | F65: =+VLOOKUP(LEFT($D$18,5),'8_Privaciones Mpio dominio'!A:AU,44,FALSE) -> 1.5
C66: Trabajo informal | D66: =+VLOOKUP(LEFT($D$18,5),'8_Privaciones Mpio dominio'!A:AU,45,FALSE) -> 69.1 | E66: =+VLOOKUP(LEFT($D$18,5),'8_Privaciones Mpio dominio'!A:AU,46,FALSE) -> 69.1 | F66: =+VLOOKUP(LEFT($D$18,5),'8_Privaciones Mpio dominio'!A:AU,47,FALSE) -> 84.4
C67: Fuente: Censo Nacional de Población y Vivienda (CNPV 2018)
C68: Fecha de publicación: 31 de enero de 2020
C87: Fuente: Censo Nacional de Población y Vivienda (CNPV 2018) | G87: Fuente: Censo Nacional de Población y Vivienda (CNPV 2018)
C107: Fuente: Censo Nacional de Población y Vivienda (CNPV 2018) | G107: Fuente: Censo Nacional de Población y Vivienda (CNPV 2018)
...
